Traceback (most recent call last):
  File "/home/zuzanna/Documents/miniconda3/envs/mgr_test/lib/python3.10/site-packages/nbclient/client.py", line 730, in _async_poll_for_reply
    msg = await ensure_async(self.kc.shell_channel.get_msg(timeout=new_timeout))
  File "/home/zuzanna/Documents/miniconda3/envs/mgr_test/lib/python3.10/site-packages/nbclient/util.py", line 96, in ensure_async
    result = await obj
  File "/home/zuzanna/Documents/miniconda3/envs/mgr_test/lib/python3.10/site-packages/jupyter_client/channels.py", line 315, in get_msg
    raise Empty
_queue.Empty

During handling of the above exception, another exception occurred:

Traceback (most recent call last):
  File "/home/zuzanna/Documents/miniconda3/envs/mgr_test/lib/python3.10/site-packages/jupyter_cache/executors/utils.py", line 58, in single_nb_execution
    executenb(
  File "/home/zuzanna/Documents/miniconda3/envs/mgr_test/lib/python3.10/site-packages/nbclient/client.py", line 1204, in execute
    return NotebookClient(nb=nb, resources=resources, km=km, **kwargs).execute()
  File "/home/zuzanna/Documents/miniconda3/envs/mgr_test/lib/python3.10/site-packages/nbclient/util.py", line 84, in wrapped
    return just_run(coro(*args, **kwargs))
  File "/home/zuzanna/Documents/miniconda3/envs/mgr_test/lib/python3.10/site-packages/nbclient/util.py", line 62, in just_run
    return loop.run_until_complete(coro)
  File "/home/zuzanna/Documents/miniconda3/envs/mgr_test/lib/python3.10/asyncio/base_events.py", line 649, in run_until_complete
    return future.result()
  File "/home/zuzanna/Documents/miniconda3/envs/mgr_test/lib/python3.10/site-packages/nbclient/client.py", line 663, in async_execute
    await self.async_execute_cell(
  File "/home/zuzanna/Documents/miniconda3/envs/mgr_test/lib/python3.10/site-packages/nbclient/client.py", line 949, in async_execute_cell
    exec_reply = await self.task_poll_for_reply
  File "/home/zuzanna/Documents/miniconda3/envs/mgr_test/lib/python3.10/site-packages/nbclient/client.py", line 754, in _async_poll_for_reply
    await self._async_handle_timeout(timeout, cell)
  File "/home/zuzanna/Documents/miniconda3/envs/mgr_test/lib/python3.10/site-packages/nbclient/client.py", line 801, in _async_handle_timeout
    raise CellTimeoutError.error_from_timeout_and_cell(
nbclient.exceptions.CellTimeoutError: A cell timed out while it was being executed, after 30 seconds.
The message was: Cell execution timed out.
Here is a preview of the cell contents:
-------------------
['out = Output(**output_args)', 'conditions = Conditions(**conditions_args)', 'solver = Solver(**solver_args)', 'main = MainSail(**main_sail_args)', 'jib = JibSail(**jib_sail_args) # j2 = JibSail(centerline_twist_deg= 15. * jgirths + 7, girths= jgirths) set centerline_twist_deg and girths, rest is default']
...
['hull = HullGeometry(rig.sheer_above_waterline, rig.foretriangle_base, csys_transformations, keel.center_of_lateral_resistance_upright)', 'myvlm = Vlm(sail_set.panels, solver.n_chordwise, solver.n_spanwise, conditions.rho, w.profile, sail_set.trailing_edge_info, sail_set.leading_edge_info)', '', 'inviscid_flow_results = InviscidFlowResults(sail_set, csys_transformations, myvlm)', 'inviscid_flow_results.estimate_heeling_moment_from_keel(hull.center_of_lateral_resistance)']
-------------------

